const handleAsyncError = (fn) => {
    return (req, res, next) => {
      Promise.resolve(fn(req, res, next)).catch(next);
    };
  };
  
  export default handleAsyncError;